Workbook

Sheet Image
C9: C | E9: A | G9: B
C10: LT MRG or CUSTOMER | D10: = | E10: PRISIM | F10: - | G10: LT MRG or CUSTOMER
C11: APPLICABLE SURCHARGES | E11: SUBJECT ALL SURCHARGES | G11: INCLUSIVE SURCHARGES
E12: column CB
C17: F | E17: D | G17: E
C18: ALL IN | D18: = | E18: ROUND 1 BENCHMARK RATES | F18: + | G18: ROUND 1 BENCHMARK RATES
C19: CALCULATION | E19: OFT + ARO + ARD | G19: APPLICABLE SURCHARGES
C23: H | E23: F | G23: C
C24: BASE FREIGHT | D24: = | E24: ALL IN | F24: - | G24: CUSTOMER
C25: CALCULATION | E25: CALCULATION | G25: APPLICABLE TO SURCHARGES

Sheet Sheet1
B2: Formula | D2: Case 1 | I2: Formula | K2: Case 2 | P2: Formula | R2: Case 3
C4: A | D4: Benchmark/Offer Rate | E4: LT MRG | J4: A | K4: Benchmark/Offer Rate | L4: LT MRG | Q4: A | R4: Benchmark/Offer Rate | S4: LT MRG
C5: B | D5: Reference Base | E5: LT MRG = Subject to OBS, THL, THD | J5: B | K5: Customer Request | L5: Subject to OBS Only | Q5: B | R5: Current Contract | S5: Subject to OBS and THL Only
C6: C | D6: Customer Request | E6: Subject to OBS Only | J6: C | K6: Customer Request | L6: Subject to OBS Only | Q6: C | R6: Customer Request | S6: Subject to OBS Only
E9: 20' | F9: 40' | G9: HC' | L9: 20' | M9: 40' | N9: HC' | S9: 20' | T9: 40' | U9: HC'
C10: A | D10: Base (LT MRG) | E10: 500 | F10: 1000 | G10: 1000 | J10: A | K10: Base (LT MRG) | L10: 500 | M10: 1000 | N10: 1000 | Q10: A | R10: Base (LT MRG) | S10: 500 | T10: 1000 | U10: 1000
C11: B | D11: OBS | E11: 60 | F11: 120 | G11: 120 | J11: B | K11: OBS | L11: 60 | M11: 120 | N11: 120 | Q11: B | R11: OBS | S11: 60 | T11: 120 | U11: 120
D12: THL | E12: 100 | F12: 200 | G12: 200 | R12: THL | S12: 100 | T12: 200 | U12: 200
D13: THD | E13: 80 | F13: 160 | G13: 160
B15: A + B | C15: D | D15: All In | E15: =SUM(E10:E13) -> 740 | F15: =SUM(F10:F13) -> 1480 | G15: =SUM(G10:G13) -> 1480 | I15: A + B | J15: D | K15: All In | L15: =SUM(L10:L13) -> 560 | M15: =SUM(M10:M13) -> 1120 | N15: =SUM(N10:N13) -> 1120 | P15: A + B | Q15: D | R15: All In | S15: =SUM(S10:S13) -> 660 | T15: =SUM(T10:T13) -> 1320 | U15: =SUM(U10:U13) -> 1320
B17: D - C | C17: E | D17: Base Rate | E17: =E15-E11 -> 680 | F17: =F15-F11 -> 1360 | G17: =G15-G11 -> 1360 | I17: D - C | J17: E | K17: Base Rate | L17: =L15-L11 -> 500 | M17: =M15-M11 -> 1000 | N17: =N15-N11 -> 1000 | P17: D - C | Q17: E | R17: Base Rate | S17: =S15-S11 -> 600 | T17: =T15-T11 -> 1200 | U17: =U15-U11 -> 1200
B21: Formula | D21: Case 4 | I21: Formula | K21: Case 5 | P21: Formula | R21: Case 6
C23: A | D23: Benchmark/Offer Rate | E23: LT MRG | J23: A | K23: Benchmark/Offer Rate | L23: LT MRG | Q23: A | R23: Benchmark/Offer Rate | S23: Manual Input By Pricer
C24: B | D24: Reference Base | E24: Subject All = OBS, THL, THD, EES | J24: B | K24: Customer Request | L24: All In | Q24: B | R24: Reference Base | S24: LT MRG = Subject to OBS, THL, THD
C25: C | D25: Customer Request | E25: Subject to OBS Only | J25: C | K25: Customer Request | L25: Subject to OBS Only | Q25: C | R25: Customer Request | S25: Subject to OBS, THL Only
E28: 20' | F28: 40' | G28: HC' | L28: 20' | M28: 40' | N28: HC' | S28: 20' | T28: 40' | U28: HC'
C29: A | D29: Base (LT MRG) | E29: 500 | F29: 1000 | G29: 1000 | J29: A | K29: Base (LT MRG) | L29: 500 | M29: 1000 | N29: 1000 | Q29: A | R29: Base (Manual Input) | S29: 450 | T29: 900 | U29: 900
C30: B | D30: OBS | E30: 60 | F30: 120 | G30: 120 | J30: B | Q30: B | R30: OBS | S30: 60 | T30: 120 | U30: 120
D31: THL | E31: 100 | F31: 200 | G31: 200 | R31: THL | S31: 100 | T31: 200 | U31: 200
D32: THD | E32: 80 | F32: 160 | G32: 160 | R32: THD | S32: 80 | T32: 160 | U32: 160
D33: EES | E33: 65 | F33: 130 | G33: 130
B34: A + B | C34: D | D34: All In | E34: =SUM(E29:E33) -> 805 | F34: =SUM(F29:F33) -> 1610 | G34: =SUM(G29:G33) -> 1610 | I34: A + B | J34: D | K34: All In | L34: =SUM(L29:L32) -> 500 | M34: =SUM(M29:M32) -> 1000 | N34: =SUM(N29:N32) -> 1000 | P34: A + B | Q34: D | R34: All In | S34: =SUM(S29:S32) -> 690 | T34: =SUM(T29:T32) -> 1380 | U34: =SUM(U29:U32) -> 1380
B36: D - C | C36: E | D36: Base Rate | E36: =E34-E30 -> 745 | F36: =F34-F30 -> 1490 | G36: =G34-G30 -> 1490 | I36: D - C | J36: E | K36: Base Rate | L36: =L34-L11 -> 440 | M36: =M34-M11 -> 880 | N36: =N34-N11 -> 880 | P36: D - C | Q36: E | R36: Base Rate | S36: =S34-S30-S31 -> 530 | T36: =T34-T30-T31 -> 1060 | U36: =U34-U30-U31 -> 1060
B55: D - C | C55: E | D55: Base Rate | E55: =E53-E49-E50 -> 0 | F55: =F53-F49-F50 -> 0 | G55: =G53-G49-G50 -> 0

Sheet Logic
B1: (1) | C1: (2) | D1: (3) | E1: (4) | F1: (4) | G1: (5) | H1: (6) | I1: (7) | K1: (8) | L1: (9) | M1: (10) | O1: (11) | P1: (12) | R1: 1231 | S1: (13) | T1: (9) | U1: (10) | W1: (12) | Z1: (14)
A2: Location/Pricing Tool Column: | B2: Back End Master | C2: 10-Original/10-2_TC Customer | D2: BS | E2: BT | F2: BU | G2: CA | H2: CB | I2: CF | K2: Pricing Tool | R2: All In Calculation | S2: CF | Y2: All In Calculation | Z2: Base Freight Result
A3: Source: | B3: OPUS Surcharge Tariff | C3: Customer's T&C | D3: CST-S | E3: CST-S | F3: CST-S | G3: Marketing LT MRG | H3: OPUS PRISIM | I3: CUSTOMER_STRUCTURE | K3: Default Displayed Surcharges | L3: Y | P3: LT_MRG | R3: =IF(P3<>"",800+P5,"") -> 1000 | S3: CUSTOMER_STRUCTURE | T3: Y | W3: LT_MRG | Y3: =800+W5 -> 950 | Z3: =IF(P3<>"",R3-M5,"") -> 773
B4: Service Scope: WEE Surcharge: All Auto Rating Surcharges Sample Port Pair: BEANR/SAJED LT MRG OFT: USD 800 | C4: Customer's Subject/Fixed | D4: Customer's Subject/Fixed | E4: Customer's Fixed | F4: Customer's Inclusive | G4: LT MRG Inclusive | H4: PRISIM Subject All | I4: Shortlisted Surcharge / Possible Applicable Surcharges | K4: Default Pricing Tool Visible | L4: Update Condition | M4: Right Hand Side Surcharges = What will Happen? | O4: New Column Inserted? | P4: What Will You Be Using For Your Benchmark Rate Offers? | R4: Will This (Column 12) Be Considered In Your All In Calculation? | S4: Shortlisted Surcharge / Possible Applicable Surcharges | T4: Update Condition | U4: Right Hand Side Surcharges = What will Happen? | W4: What Will You Be Using For Your Benchmark Rate Offers? | Y4: Will This (Column 12) Be Considered In Your All In Calculation?
A5: Dummy Value (for Visualization) | I5: =SUM(J6:J70) -> 227 | M5: =SUMIF(M6:M70,"Subject/Fixed",N6:N70) -> 227 | P5: =SUMIF(R6:R70,"Yes",Q6:Q70) -> 200 | U5: =SUMIF(U6:U70,"Subject/Fixed",V6:V70) -> 227 | W5: =SUMIF(Y6:Y70,"Yes",X6:X70) -> 150
B6: ADC | C6: IN TEXT | F6: ADC | I6: =IF($I$3="","",IF($I$3="LT_MRG",IF($H6="","",IF($G6="",$H6,"")),IF($H6="","",IF($F6="",$H6,"")))) | J6: =IFERROR(VLOOKUP(I6,'Dummy Amount'!$A$2:$B$66,2,FALSE),0) -> 0 | K6: AGS | L6: =IF($L$3="Y",IF($I6="",IF($K6<>"",$K6,""),$I6),"") -> AGS | M6: =IF(L6="","",IF(I6<>"","Subject/Fixed","Inclusive")) -> Inclusive | N6: =IFERROR(VLOOKUP(L6,'Dummy Amount'!A2:B66,2,FALSE),0) -> 0 | O6: =IF(L6="","",IF(I6="","No",IF(K6="","Yes","No"))) -> No | P6: =IF($P$3="","",IF($P$3="LT_MRG",IF($H6="","",IF($G6="",$H6,"")),IF($H6="","",IF($F6="",$H6,"")))) | Q6: =IFERROR(VLOOKUP(P6,'Dummy Amount'!$A$2:$B$66,2,FALSE),0) -> 0 | R6: =IF(P6="","",IF(L6="","No","Yes")) | S6: =IF(Q6="","",IF(M6="","No","Yes")) -> Yes | T6: =IF(R6="","",IF(N6="","No","Yes")) | U6: =IF(S6="","",IF(O6="","No","Yes")) -> Yes | V6: =IF(T6="","",IF(P6="","No","Yes")) | W6: =IF(U6="","",IF(Q6="","No","Yes")) -> Yes | X6: =IF(V6="","",IF(R6="","No","Yes")) | Y6: =IF(W6="","",IF(S6="","No","Yes")) -> Yes
B7: ADD | F7: ADD | I7: =IF($I$3="","",IF($I$3="LT_MRG",IF($H7="","",IF($G7="",$H7,"")),IF($H7="","",IF($F7="",$H7,"")))) | J7: =IFERROR(VLOOKUP(I7,'Dummy Amount'!$A$2:$B$66,2,FALSE),0) -> 0 | L7: =IF($L$3="Y",IF($I7="",IF($K7<>"",$K7,""),$I7),"") | M7: =IF(L7="","",IF(I7<>"","Subject/Fixed","Inclusive")) | N7: =IFERROR(VLOOKUP(L7,'Dummy Amount'!A3:B67,2,FALSE),0) -> 0 | O7: =IF(L7="","",IF(I7="","No",IF(K7="","Yes","No"))) | P7: =IF($P$3="","",IF($P$3="LT_MRG",IF($H7="","",IF($G7="",$H7,"")),IF($H7="","",IF($F7="",$H7,"")))) | Q7: =IFERROR(VLOOKUP(P7,'Dummy Amount'!$A$2:$B$66,2,FALSE),0) -> 0 | R7: =IF(P7="","",IF(L7="","No","Yes")) | S7: =IF($S$3="","",IF($S$3="LT_MRG",IF($H7="","",IF($G7="",$H7,"")),IF($H7="","",IF($F7="",$H7,"")))) | T7: =IF($T$3="Y",IF($S7="",IF($L7<>"",$L7,""),$S7),"") | U7: =IF(T7="","",IF(S7<>"","Subject/Fixed","Inclusive")) | V7: =IFERROR(VLOOKUP(T7,'Dummy Amount'!$A$2:$B$66,2,FALSE),0) -> 0 | W7: =IF($W$3="","",IF($P$3="LT_MRG",IF($H7="","",IF($G7="",$H7,"")),IF($H7="","",IF($F7="",$H7,"")))) | X7: =IFERROR(VLOOKUP(W7,'Dummy Amount'!$A$2:$B$66,2,FALSE),0) -> 0 | Y7: =IF(W7="","",IF(T7="","No",IF(U7="Inclusive","No","Yes")))
B8: AHA | F8: AHA | I8: =IF($I$3="","",IF($I$3="LT_MRG",IF($H8="","",IF($G8="",$H8,"")),IF($H8="","",IF($F8="",$H8,"")))) | J8: =IFERROR(VLOOKUP(I8,'Dummy Amount'!$A$2:$B$66,2,FALSE),0) -> 0 | L8: =IF($L$3="Y",IF($I8="",IF($K8<>"",$K8,""),$I8),"") | M8: =IF(L8="","",IF(I8<>"","Subject/Fixed","Inclusive")) | N8: =IFERROR(VLOOKUP(L8,'Dummy Amount'!A4:B68,2,FALSE),0) -> 0 | O8: =IF(L8="","",IF(I8="","No",IF(K8="","Yes","No"))) | P8: =IF($P$3="","",IF($P$3="LT_MRG",IF($H8="","",IF($G8="",$H8,"")),IF($H8="","",IF($F8="",$H8,"")))) | Q8: =IFERROR(VLOOKUP(P8,'Dummy Amount'!$A$2:$B$66,2,FALSE),0) -> 0 | R8: =IF(P8="","",IF(L8="","No","Yes")) | S8: =IF($S$3="","",IF($S$3="LT_MRG",IF($H8="","",IF($G8="",$H8,"")),IF($H8="","",IF($F8="",$H8,"")))) | T8: =IF($T$3="Y",IF($S8="",IF($L8<>"",$L8,""),$S8),"") | U8: =IF(T8="","",IF(S8<>"","Subject/Fixed","Inclusive")) | V8: =IFERROR(VLOOKUP(T8,'Dummy Amount'!$A$2:$B$66,2,FALSE),0) -> 0 | W8: =IF($W$3="","",IF($P$3="LT_MRG",IF($H8="","",IF($G8="",$H8,"")),IF($H8="","",IF($F8="",$H8,"")))) | X8: =IFERROR(VLOOKUP(W8,'Dummy Amount'!$A$2:$B$66,2,FALSE),0) -> 0 | Y8: =IF(W8="","",IF(T8="","No",IF(U8="Inclusive","No","Yes")))
B9: AMS | D9: AMS | I9: =IF($I$3="","",IF($I$3="LT_MRG",IF($H9="","",IF($G9="",$H9,"")),IF($H9="","",IF($F9="",$H9,"")))) | J9: =IFERROR(VLOOKUP(I9,'Dummy Amount'!$A$2:$B$66,2,FALSE),0) -> 0 | K9: AMS | L9: =IF($L$3="Y",IF($I9="",IF($K9<>"",$K9,""),$I9),"") -> AMS | M9: =IF(L9="","",IF(I9<>"","Subject/Fixed","Inclusive")) -> Inclusive | N9: =IFERROR(VLOOKUP(L9,'Dummy Amount'!A5:B69,2,FALSE),0) -> 50 | O9: =IF(L9="","",IF(I9="","No",IF(K9="","Yes","No"))) -> No | P9: =IF($P$3="","",IF($P$3="LT_MRG",IF($H9="","",IF($G9="",$H9,"")),IF($H9="","",IF($F9="",$H9,"")))) | Q9: =IFERROR(VLOOKUP(P9,'Dummy Amount'!$A$2:$B$66,2,FALSE),0) -> 0 | R9: =IF(P9="","",IF(L9="","No","Yes")) | S9: =IF($S$3="","",IF($S$3="LT_MRG",IF($H9="","",IF($G9="",$H9,"")),IF($H9="","",IF($F9="",$H9,"")))) | T9: =IF($T$3="Y",IF($S9="",IF($L9<>"",$L9,""),$S9),"") -> AMS | U9: =IF(T9="","",IF(S9<>"","Subject/Fixed","Inclusive")) -> Inclusive | V9: =IFERROR(VLOOKUP(T9,'Dummy Amount'!$A$2:$B$66,2,FALSE),0) -> 50 | W9: =IF($W$3="","",IF($P$3="LT_MRG",IF($H9="","",IF($G9="",$H9,"")),IF($H9="","",IF($F9="",$H9,"")))) | X9: =IFERROR(VLOOKUP(W9,'Dummy Amount'!$A$2:$B$66,2,FALSE),0) -> 0 | Y9: =IF(W9="","",IF(T9="","No",IF(U9="Inclusive","No","Yes")))
B10: BSC | F10: BSC | I10: =IF($I$3="","",IF($I$3="LT_MRG",IF($H10="","",IF($G10="",$H10,"")),IF($H10="","",IF($F10="",$H10,"")))) | J10: =IFERROR(VLOOKUP(I10,'Dummy Amount'!$A$2:$B$66,2,FALSE),0) -> 0 | L10: =IF($L$3="Y",IF($I10="",IF($K10<>"",$K10,""),$I10),"") | M10: =IF(L10="","",IF(I10<>"","Subject/Fixed","Inclusive")) | N10: =IFERROR(VLOOKUP(L10,'Dummy Amount'!A6:B70,2,FALSE),0) -> 0 | O10: =IF(L10="","",IF(I10="","No",IF(K10="","Yes","No"))) | P10: =IF($P$3="","",IF($P$3="LT_MRG",IF($H10="","",IF($G10="",$H10,"")),IF($H10="","",IF($F10="",$H10,"")))) | Q10: =IFERROR(VLOOKUP(P10,'Dummy Amount'!$A$2:$B$66,2,FALSE),0) -> 0 | R10: =IF(P10="","",IF(L10="","No","Yes")) | S10: =IF($S$3="","",IF($S$3="LT_MRG",IF($H10="","",IF($G10="",$H10,"")),IF($H10="","",IF($F10="",$H10,"")))) | T10: =IF($T$3="Y",IF($S10="",IF($L10<>"",$L10,""),$S10),"") | U10: =IF(T10="","",IF(S10<>"","Subject/Fixed","Inclusive")) | V10: =IFERROR(VLOOKUP(T10,'Dummy Amount'!$A$2:$B$66,2,FALSE),0) -> 0 | W10: =IF($W$3="","",IF($P$3="LT_MRG",IF($H10="","",IF($G10="",$H10,"")),IF($H10="","",IF($F10="",$H10,"")))) | X10: =IFERROR(VLOOKUP(W10,'Dummy Amount'!$A$2:$B$66,2,FALSE),0) -> 0 | Y10: =IF(W10="","",IF(T10="","No",IF(U10="Inclusive","No","Yes")))
B11: CAF | F11: CAF | G11: CAF | I11: =IF($I$3="","",IF($I$3="LT_MRG",IF($H11="","",IF($G11="",$H11,"")),IF($H11="","",IF($F11="",$H11,"")))) | J11: =IFERROR(VLOOKUP(I11,'Dummy Amount'!$A$2:$B$66,2,FALSE),0) -> 0 | L11: =IF($L$3="Y",IF($I11="",IF($K11<>"",$K11,""),$I11),"") | M11: =IF(L11="","",IF(I11<>"","Subject/Fixed","Inclusive")) | N11: =IFERROR(VLOOKUP(L11,'Dummy Amount'!A7:B71,2,FALSE),0) -> 0 | O11: =IF(L11="","",IF(I11="","No",IF(K11="","Yes","No"))) | P11: =IF($P$3="","",IF($P$3="LT_MRG",IF($H11="","",IF($G11="",$H11,"")),IF($H11="","",IF($F11="",$H11,"")))) | Q11: =IFERROR(VLOOKUP(P11,'Dummy Amount'!$A$2:$B$66,2,FALSE),0) -> 0 | R11: =IF(P11="","",IF(L11="","No","Yes")) | S11: =IF($S$3="","",IF($S$3="LT_MRG",IF($H11="","",IF($G11="",$H11,"")),IF($H11="","",IF($F11="",$H11,"")))) | T11: =IF($T$3="Y",IF($S11="",IF($L11<>"",$L11,""),$S11),"") | U11: =IF(T11="","",IF(S11<>"","Subject/Fixed","Inclusive")) | V11: =IFERROR(VLOOKUP(T11,'Dummy Amount'!$A$2:$B$66,2,FALSE),0) -> 0 | W11: =IF($W$3="","",IF($P$3="LT_MRG",IF($H11="","",IF($G11="",$H11,"")),IF($H11="","",IF($F11="",$H11,"")))) | X11: =IFERROR(VLOOKUP(W11,'Dummy Amount'!$A$2:$B$66,2,FALSE),0) -> 0 | Y11: =IF(W11="","",IF(T11="","No",IF(U11="Inclusive","No","Yes")))
B12: CCC | F12: CCC | I12: =IF($I$3="","",IF($I$3="LT_MRG",IF($H12="","",IF($G12="",$H12,"")),IF($H12="","",IF($F12="",$H12,"")))) | J12: =IFERROR(VLOOKUP(I12,'Dummy Amount'!$A$2:$B$66,2,FALSE),0) -> 0 | L12: =IF($L$3="Y",IF($I12="",IF($K12<>"",$K12,""),$I12),"") | M12: =IF(L12="","",IF(I12<>"","Subject/Fixed","Inclusive")) | N12: =IFERROR(VLOOKUP(L12,'Dummy Amount'!A8:B72,2,FALSE),0) -> 0 | O12: =IF(L12="","",IF(I12="","No",IF(K12="","Yes","No"))) | P12: =IF($P$3="","",IF($P$3="LT_MRG",IF($H12="","",IF($G12="",$H12,"")),IF($H12="","",IF($F12="",$H12,"")))) | Q12: =IFERROR(VLOOKUP(P12,'Dummy Amount'!$A$2:$B$66,2,FALSE),0) -> 0 | R12: =IF(P12="","",IF(L12="","No","Yes")) | S12: =IF($S$3="","",IF($S$3="LT_MRG",IF($H12="","",IF($G12="",$H12,"")),IF($H12="","",IF($F12="",$H12,"")))) | T12: =IF($T$3="Y",IF($S12="",IF($L12<>"",$L12,""),$S12),"") | U12: =IF(T12="","",IF(S12<>"","Subject/Fixed","Inclusive")) | V12: =IFERROR(VLOOKUP(T12,'Dummy Amount'!$A$2:$B$66,2,FALSE),0) -> 0 | W12: =IF($W$3="","",IF($P$3="LT_MRG",IF($H12="","",IF($G12="",$H12,"")),IF($H12="","",IF($F12="",$H12,"")))) | X12: =IFERROR(VLOOKUP(W12,'Dummy Amount'!$A$2:$B$66,2,FALSE),0) -> 0 | Y12: =IF(W12="","",IF(T12="","No",IF(U12="Inclusive","No","Yes")))
B13: CCU | F13: CCU | I13: =IF($I$3="","",IF($I$3="LT_MRG",IF($H13="","",IF($G13="",$H13,"")),IF($H13="","",IF($F13="",$H13,"")))) | J13: =IFERROR(VLOOKUP(I13,'Dummy Amount'!$A$2:$B$66,2,FALSE),0) -> 0 | L13: =IF($L$3="Y",IF($I13="",IF($K13<>"",$K13,""),$I13),"") | M13: =IF(L13="","",IF(I13<>"","Subject/Fixed","Inclusive")) | N13: =IFERROR(VLOOKUP(L13,'Dummy Amount'!A9:B73,2,FALSE),0) -> 0 | O13: =IF(L13="","",IF(I13="","No",IF(K13="","Yes","No"))) | P13: =IF($P$3="","",IF($P$3="LT_MRG",IF($H13="","",IF($G13="",$H13,"")),IF($H13="","",IF($F13="",$H13,"")))) | Q13: =IFERROR(VLOOKUP(P13,'Dummy Amount'!$A$2:$B$66,2,FALSE),0) -> 0 | R13: =IF(P13="","",IF(L13="","No","Yes")) | S13: =IF($S$3="","",IF($S$3="LT_MRG",IF($H13="","",IF($G13="",$H13,"")),IF($H13="","",IF($F13="",$H13,"")))) | T13: =IF($T$3="Y",IF($S13="",IF($L13<>"",$L13,""),$S13),"") | U13: =IF(T13="","",IF(S13<>"","Subject/Fixed","Inclusive")) | V13: =IFERROR(VLOOKUP(T13,'Dummy Amount'!$A$2:$B$66,2,FALSE),0) -> 0 | W13: =IF($W$3="","",IF($P$3="LT_MRG",IF($H13="","",IF($G13="",$H13,"")),IF($H13="","",IF($F13="",$H13,"")))) | X13: =IFERROR(VLOOKUP(W13,'Dummy Amount'!$A$2:$B$66,2,FALSE),0) -> 0 | Y13: =IF(W13="","",IF(T13="","No",IF(U13="Inclusive","No","Yes")))
B14: CFD | F14: CFD | I14: =IF($I$3="","",IF($I$3="LT_MRG",IF($H14="","",IF($G14="",$H14,"")),IF($H14="","",IF($F14="",$H14,"")))) | J14: =IFERROR(VLOOKUP(I14,'Dummy Amount'!$A$2:$B$66,2,FALSE),0) -> 0 | L14: =IF($L$3="Y",IF($I14="",IF($K14<>"",$K14,""),$I14),"") | M14: =IF(L14="","",IF(I14<>"","Subject/Fixed","Inclusive")) | N14: =IFERROR(VLOOKUP(L14,'Dummy Amount'!A10:B74,2,FALSE),0) -> 0 | O14: =IF(L14="","",IF(I14="","No",IF(K14="","Yes","No"))) | P14: =IF($P$3="","",IF($P$3="LT_MRG",IF($H14="","",IF($G14="",$H14,"")),IF($H14="","",IF($F14="",$H14,"")))) | Q14: =IFERROR(VLOOKUP(P14,'Dummy Amount'!$A$2:$B$66,2,FALSE),0) -> 0 | R14: =IF(P14="","",IF(L14="","No","Yes")) | S14: =IF($S$3="","",IF($S$3="LT_MRG",IF($H14="","",IF($G14="",$H14,"")),IF($H14="","",IF($F14="",$H14,"")))) | T14: =IF($T$3="Y",IF($S14="",IF($L14<>"",$L14,""),$S14),"") | U14: =IF(T14="","",IF(S14<>"","Subject/Fixed","Inclusive")) | V14: =IFERROR(VLOOKUP(T14,'Dummy Amount'!$A$2:$B$66,2,FALSE),0) -> 0 | W14: =IF($W$3="","",IF($P$3="LT_MRG",IF($H14="","",IF($G14="",$H14,"")),IF($H14="","",IF($F14="",$H14,"")))) | X14: =IFERROR(VLOOKUP(W14,'Dummy Amount'!$A$2:$B$66,2,FALSE),0) -> 0 | Y14: =IF(W14="","",IF(T14="","No",IF(U14="Inclusive","No","Yes")))
B15: CFD | F15: CFD | I15: =IF($I$3="","",IF($I$3="LT_MRG",IF($H15="","",IF($G15="",$H15,"")),IF($H15="","",IF($F15="",$H15,"")))) | J15: =IFERROR(VLOOKUP(I15,'Dummy Amount'!$A$2:$B$66,2,FALSE),0) -> 0 | L15: =IF($L$3="Y",IF($I15="",IF($K15<>"",$K15,""),$I15),"") | M15: =IF(L15="","",IF(I15<>"","Subject/Fixed","Inclusive")) | N15: =IFERROR(VLOOKUP(L15,'Dummy Amount'!A11:B75,2,FALSE),0) -> 0 | O15: =IF(L15="","",IF(I15="","No",IF(K15="","Yes","No"))) | P15: =IF($P$3="","",IF($P$3="LT_MRG",IF($H15="","",IF($G15="",$H15,"")),IF($H15="","",IF($F15="",$H15,"")))) | Q15: =IFERROR(VLOOKUP(P15,'Dummy Amount'!$A$2:$B$66,2,FALSE),0) -> 0 | R15: =IF(P15="","",IF(L15="","No","Yes")) | S15: =IF($S$3="","",IF($S$3="LT_MRG",IF($H15="","",IF($G15="",$H15,"")),IF($H15="","",IF($F15="",$H15,"")))) | T15: =IF($T$3="Y",IF($S15="",IF($L15<>"",$L15,""),$S15),"") | U15: =IF(T15="","",IF(S15<>"","Subject/Fixed","Inclusive")) | V15: =IFERROR(VLOOKUP(T15,'Dummy Amount'!$A$2:$B$66,2,FALSE),0) -> 0 | W15: =IF($W$3="","",IF($P$3="LT_MRG",IF($H15="","",IF($G15="",$H15,"")),IF($H15="","",IF($F15="",$H15,"")))) | X15: =IFERROR(VLOOKUP(W15,'Dummy Amount'!$A$2:$B$66,2,FALSE),0) -> 0 | Y15: =IF(W15="","",IF(T15="","No",IF(U15="Inclusive","No","Yes")))
B16: CGD | F16: CGD | I16: =IF($I$3="","",IF($I$3="LT_MRG",IF($H16="","",IF($G16="",$H16,"")),IF($H16="","",IF($F16="",$H16,"")))) | J16: =IFERROR(VLOOKUP(I16,'Dummy Amount'!$A$2:$B$66,2,FALSE),0) -> 0 | L16: =IF($L$3="Y",IF($I16="",IF($K16<>"",$K16,""),$I16),"") | M16: =IF(L16="","",IF(I16<>"","Subject/Fixed","Inclusive")) | N16: =IFERROR(VLOOKUP(L16,'Dummy Amount'!A12:B76,2,FALSE),0) -> 0 | O16: =IF(L16="","",IF(I16="","No",IF(K16="","Yes","No"))) | P16: =IF($P$3="","",IF($P$3="LT_MRG",IF($H16="","",IF($G16="",$H16,"")),IF($H16="","",IF($F16="",$H16,"")))) | Q16: =IFERROR(VLOOKUP(P16,'Dummy Amount'!$A$2:$B$66,2,FALSE),0) -> 0 | R16: =IF(P16="","",IF(L16="","No","Yes")) | S16: =IF($S$3="","",IF($S$3="LT_MRG",IF($H16="","",IF($G16="",$H16,"")),IF($H16="","",IF($F16="",$H16,"")))) | T16: =IF($T$3="Y",IF($S16="",IF($L16<>"",$L16,""),$S16),"") | U16: =IF(T16="","",IF(S16<>"","Subject/Fixed","Inclusive")) | V16: =IFERROR(VLOOKUP(T16,'Dummy Amount'!$A$2:$B$66,2,FALSE),0) -> 0 | W16: =IF($W$3="","",IF($P$3="LT_MRG",IF($H16="","",IF($G16="",$H16,"")),IF($H16="","",IF($F16="",$H16,"")))) | X16: =IFERROR(VLOOKUP(W16,'Dummy Amount'!$A$2:$B$66,2,FALSE),0) -> 0 | Y16: =IF(W16="","",IF(T16="","No",IF(U16="Inclusive","No","Yes")))
B17: CMC | F17: CMC | I17: =IF($I$3="","",IF($I$3="LT_MRG",IF($H17="","",IF($G17="",$H17,"")),IF($H17="","",IF($F17="",$H17,"")))) | J17: =IFERROR(VLOOKUP(I17,'Dummy Amount'!$A$2:$B$66,2,FALSE),0) -> 0 | L17: =IF($L$3="Y",IF($I17="",IF($K17<>"",$K17,""),$I17),"") | M17: =IF(L17="","",IF(I17<>"","Subject/Fixed","Inclusive")) | N17: =IFERROR(VLOOKUP(L17,'Dummy Amount'!A13:B77,2,FALSE),0) -> 0 | O17: =IF(L17="","",IF(I17="","No",IF(K17="","Yes","No"))) | P17: =IF($P$3="","",IF($P$3="LT_MRG",IF($H17="","",IF($G17="",$H17,"")),IF($H17="","",IF($F17="",$H17,"")))) | Q17: =IFERROR(VLOOKUP(P17,'Dummy Amount'!$A$2:$B$66,2,FALSE),0) -> 0 | R17: =IF(P17="","",IF(L17="","No","Yes")) | S17: =IF($S$3="","",IF($S$3="LT_MRG",IF($H17="","",IF($G17="",$H17,"")),IF($H17="","",IF($F17="",$H17,"")))) | T17: =IF($T$3="Y",IF($S17="",IF($L17<>"",$L17,""),$S17),"") | U17: =IF(T17="","",IF(S17<>"","Subject/Fixed","Inclusive")) | V17: =IFERROR(VLOOKUP(T17,'Dummy Amount'!$A$2:$B$66,2,FALSE),0) -> 0 | W17: =IF($W$3="","",IF($P$3="LT_MRG",IF($H17="","",IF($G17="",$H17,"")),IF($H17="","",IF($F17="",$H17,"")))) | X17: =IFERROR(VLOOKUP(W17,'Dummy Amount'!$A$2:$B$66,2,FALSE),0) -> 0 | Y17: =IF(W17="","",IF(T17="","No",IF(U17="Inclusive","No","Yes")))
I18: =IF($I$3="","",IF($I$3="LT_MRG",IF($H18="","",IF($G18="",$H18,"")),IF($H18="","",IF($F18="",$H18,"")))) | J18: =IFERROR(VLOOKUP(I18,'Dummy Amount'!$A$2:$B$66,2,FALSE),0) -> 0 | K18: CMD | L18: =IF($L$3="Y",IF($I18="",IF($K18<>"",$K18,""),$I18),"") -> CMD | M18: =IF(L18="","",IF(I18<>"","Subject/Fixed","Inclusive")) -> Inclusive | N18: =IFERROR(VLOOKUP(L18,'Dummy Amount'!A14:B78,2,FALSE),0) -> 50 | O18: =IF(L18="","",IF(I18="","No",IF(K18="","Yes","No"))) -> No | P18: =IF($P$3="","",IF($P$3="LT_MRG",IF($H18="","",IF($G18="",$H18,"")),IF($H18="","",IF($F18="",$H18,"")))) | Q18: =IFERROR(VLOOKUP(P18,'Dummy Amount'!$A$2:$B$66,2,FALSE),0) -> 0 | R18: =IF(P18="","",IF(L18="","No","Yes")) | S18: =IF($S$3="","",IF($S$3="LT_MRG",IF($H18="","",IF($G18="",$H18,"")),IF($H18="","",IF($F18="",$H18,"")))) | T18: =IF($T$3="Y",IF($S18="",IF($L18<>"",$L18,""),$S18),"") -> CMD | U18: =IF(T18="","",IF(S18<>"","Subject/Fixed","Inclusive")) -> Inclusive | V18: =IFERROR(VLOOKUP(T18,'Dummy Amount'!$A$2:$B$66,2,FALSE),0) -> 50 | W18: =IF($W$3="","",IF($P$3="LT_MRG",IF($H18="","",IF($G18="",$H18,"")),IF($H18="","",IF($F18="",$H18,"")))) | X18: =IFERROR(VLOOKUP(W18,'Dummy Amount'!$A$2:$B$66,2,FALSE),0) -> 0 | Y18: =IF(W18="","",IF(T18="","No",IF(U18="Inclusive","No","Yes")))
I19: =IF($I$3="","",IF($I$3="LT_MRG",IF($H19="","",IF($G19="",$H19,"")),IF($H19="","",IF($F19="",$H19,"")))) | J19: =IFERROR(VLOOKUP(I19,'Dummy Amount'!$A$2:$B$66,2,FALSE),0) -> 0 | K19: CML | L19: =IF($L$3="Y",IF($I19="",IF($K19<>"",$K19,""),$I19),"") -> CML | M19: =IF(L19="","",IF(I19<>"","Subject/Fixed","Inclusive")) -> Inclusive | N19: =IFERROR(VLOOKUP(L19,'Dummy Amount'!A15:B79,2,FALSE),0) -> 50 | O19: =IF(L19="","",IF(I19="","No",IF(K19="","Yes","No"))) -> No | P19: =IF($P$3="","",IF($P$3="LT_MRG",IF($H19="","",IF($G19="",$H19,"")),IF($H19="","",IF($F19="",$H19,"")))) | Q19: =IFERROR(VLOOKUP(P19,'Dummy Amount'!$A$2:$B$66,2,FALSE),0) -> 0 | R19: =IF(P19="","",IF(L19="","No","Yes")) | S19: =IF($S$3="","",IF($S$3="LT_MRG",IF($H19="","",IF($G19="",$H19,"")),IF($H19="","",IF($F19="",$H19,"")))) | T19: =IF($T$3="Y",IF($S19="",IF($L19<>"",$L19,""),$S19),"") -> CML | U19: =IF(T19="","",IF(S19<>"","Subject/Fixed","Inclusive")) -> Inclusive | V19: =IFERROR(VLOOKUP(T19,'Dummy Amount'!$A$2:$B$66,2,FALSE),0) -> 50 | W19: =IF($W$3="","",IF($P$3="LT_MRG",IF($H19="","",IF($G19="",$H19,"")),IF($H19="","",IF($F19="",$H19,"")))) | X19: =IFERROR(VLOOKUP(W19,'Dummy Amount'!$A$2:$B$66,2,FALSE),0) -> 0 | Y19: =IF(W19="","",IF(T19="","No",IF(U19="Inclusive","No","Yes")))
I20: =IF($I$3="","",IF($I$3="LT_MRG",IF($H20="","",IF($G20="",$H20,"")),IF($H20="","",IF($F20="",$H20,"")))) | J20: =IFERROR(VLOOKUP(I20,'Dummy Amount'!$A$2:$B$66,2,FALSE),0) -> 0 | K20: CSC | L20: =IF($L$3="Y",IF($I20="",IF($K20<>"",$K20,""),$I20),"") -> CSC | M20: =IF(L20="","",IF(I20<>"","Subject/Fixed","Inclusive")) -> Inclusive | N20: =IFERROR(VLOOKUP(L20,'Dummy Amount'!A16:B80,2,FALSE),0) -> 50 | O20: =IF(L20="","",IF(I20="","No",IF(K20="","Yes","No"))) -> No | P20: =IF($P$3="","",IF($P$3="LT_MRG",IF($H20="","",IF($G20="",$H20,"")),IF($H20="","",IF($F20="",$H20,"")))) | Q20: =IFERROR(VLOOKUP(P20,'Dummy Amount'!$A$2:$B$66,2,FALSE),0) -> 0 | R20: =IF(P20="","",IF(L20="","No","Yes")) | S20: =IF($S$3="","",IF($S$3="LT_MRG",IF($H20="","",IF($G20="",$H20,"")),IF($H20="","",IF($F20="",$H20,"")))) | T20: =IF($T$3="Y",IF($S20="",IF($L20<>"",$L20,""),$S20),"") -> CSC | U20: =IF(T20="","",IF(S20<>"","Subject/Fixed","Inclusive")) -> Inclusive | V20: =IFERROR(VLOOKUP(T20,'Dummy Amount'!$A$2:$B$66,2,FALSE),0) -> 50 | W20: =IF($W$3="","",IF($P$3="LT_MRG",IF($H20="","",IF($G20="",$H20,"")),IF($H20="","",IF($F20="",$H20,"")))) | X20: =IFERROR(VLOOKUP(W20,'Dummy Amount'!$A$2:$B$66,2,FALSE),0) -> 0 | Y20: =IF(W20="","",IF(T20="","No",IF(U20="Inclusive","No","Yes")))
B21: CSS | F21: CSS | H21: CSS | I21: =IF($I$3="","",IF($I$3="LT_MRG",IF($H21="","",IF($G21="",$H21,"")),IF($H21="","",IF($F21="",$H21,"")))) | J21: =IFERROR(VLOOKUP(I21,'Dummy Amount'!$A$2:$B$66,2,FALSE),0) -> 0 | K21: CSS | L21: =IF($L$3="Y",IF($I21="",IF($K21<>"",$K21,""),$I21),"") -> CSS | M21: =IF(L21="","",IF(I21<>"","Subject/Fixed","Inclusive")) -> Inclusive | N21: =IFERROR(VLOOKUP(L21,'Dummy Amount'!A17:B81,2,FALSE),0) -> 50 | O21: =IF(L21="","",IF(I21="","No",IF(K21="","Yes","No"))) -> No | P21: =IF($P$3="","",IF($P$3="LT_MRG",IF($H21="","",IF($G21="",$H21,"")),IF($H21="","",IF($F21="",$H21,"")))) -> CSS | Q21: =IFERROR(VLOOKUP(P21,'Dummy Amount'!$A$2:$B$66,2,FALSE),0) -> 50 | R21: =IF(P21="","",IF(L21="","No","Yes")) -> Yes | S21: =IF($S$3="","",IF($S$3="LT_MRG",IF($H21="","",IF($G21="",$H21,"")),IF($H21="","",IF($F21="",$H21,"")))) | T21: =IF($T$3="Y",IF($S21="",IF($L21<>"",$L21,""),$S21),"") -> CSS | U21: =IF(T21="","",IF(S21<>"","Subject/Fixed","Inclusive")) -> Inclusive | V21: =IFERROR(VLOOKUP(T21,'Dummy Amount'!$A$2:$B$66,2,FALSE),0) -> 50 | W21: =IF($W$3="","",IF($P$3="LT_MRG",IF($H21="","",IF($G21="",$H21,"")),IF($H21="","",IF($F21="",$H21,"")))) -> CSS | X21: =IFERROR(VLOOKUP(W21,'Dummy Amount'!$A$2:$B$66,2,FALSE),0) -> 50 | Y21: =IF(W21="","",IF(T21="","No",IF(U21="Inclusive","No","Yes"))) -> No
B22: CVC | F22: CVC | I22: =IF($I$3="","",IF($I$3="LT_MRG",IF($H22="","",IF($G22="",$H22,"")),IF($H22="","",IF($F22="",$H22,"")))) | J22: =IFERROR(VLOOKUP(I22,'Dummy Amount'!$A$2:$B$66,2,FALSE),0) -> 0 | L22: =IF($L$3="Y",IF($I22="",IF($K22<>"",$K22,""),$I22),"") | M22: =IF(L22="","",IF(I22<>"","Subject/Fixed","Inclusive")) | N22: =IFERROR(VLOOKUP(L22,'Dummy Amount'!A18:B82,2,FALSE),0) -> 0 | O22: =IF(L22="","",IF(I22="","No",IF(K22="","Yes","No"))) | P22: =IF($P$3="","",IF($P$3="LT_MRG",IF($H22="","",IF($G22="",$H22,"")),IF($H22="","",IF($F22="",$H22,"")))) | Q22: =IFERROR(VLOOKUP(P22,'Dummy Amount'!$A$2:$B$66,2,FALSE),0) -> 0 | R22: =IF(P22="","",IF(L22="","No","Yes")) | S22: =IF($S$3="","",IF($S$3="LT_MRG",IF($H22="","",IF($G22="",$H22,"")),IF($H22="","",IF($F22="",$H22,"")))) | T22: =IF($T$3="Y",IF($S22="",IF($L22<>"",$L22,""),$S22),"") | U22: =IF(T22="","",IF(S22<>"","Subject/Fixed","Inclusive")) | V22: =IFERROR(VLOOKUP(T22,'Dummy Amount'!$A$2:$B$66,2,FALSE),0) -> 0 | W22: =IF($W$3="","",IF($P$3="LT_MRG",IF($H22="","",IF($G22="",$H22,"")),IF($H22="","",IF($F22="",$H22,"")))) | X22: =IFERROR(VLOOKUP(W22,'Dummy Amount'!$A$2:$B$66,2,FALSE),0) -> 0 | Y22: =IF(W22="","",IF(T22="","No",IF(U22="Inclusive","No","Yes")))
I23: =IF($I$3="","",IF($I$3="LT_MRG",IF($H23="","",IF($G23="",$H23,"")),IF($H23="","",IF($F23="",$H23,"")))) | J23: =IFERROR(VLOOKUP(I23,'Dummy Amount'!$A$2:$B$66,2,FALSE),0) -> 0 | K23: CYR | L23: =IF($L$3="Y",IF($I23="",IF($K23<>"",$K23,""),$I23),"") -> CYR | M23: =IF(L23="","",IF(I23<>"","Subject/Fixed","Inclusive")) -> Inclusive | N23: =IFERROR(VLOOKUP(L23,'Dummy Amount'!A19:B83,2,FALSE),0) -> 50 | O23: =IF(L23="","",IF(I23="","No",IF(K23="","Yes","No"))) -> No | P23: =IF($P$3="","",IF($P$3="LT_MRG",IF($H23="","",IF($G23="",$H23,"")),IF($H23="","",IF($F23="",$H23,"")))) | Q23: =IFERROR(VLOOKUP(P23,'Dummy Amount'!$A$2:$B$66,2,FALSE),0) -> 0 | R23: =IF(P23="","",IF(L23="","No","Yes")) | S23: =IF($S$3="","",IF($S$3="LT_MRG",IF($H23="","",IF($G23="",$H23,"")),IF($H23="","",IF($F23="",$H23,"")))) | T23: =IF($T$3="Y",IF($S23="",IF($L23<>"",$L23,""),$S23),"") -> CYR | U23: =IF(T23="","",IF(S23<>"","Subject/Fixed","Inclusive")) -> Inclusive | V23: =IFERROR(VLOOKUP(T23,'Dummy Amount'!$A$2:$B$66,2,FALSE),0) -> 50 | W23: =IF($W$3="","",IF($P$3="LT_MRG",IF($H23="","",IF($G23="",$H23,"")),IF($H23="","",IF($F23="",$H23,"")))) | X23: =IFERROR(VLOOKUP(W23,'Dummy Amount'!$A$2:$B$66,2,FALSE),0) -> 0 | Y23: =IF(W23="","",IF(T23="","No",IF(U23="Inclusive","No","Yes")))
B24: DGS | F24: DGS | I24: =IF($I$3="","",IF($I$3="LT_MRG",IF($H24="","",IF($G24="",$H24,"")),IF($H24="","",IF($F24="",$H24,"")))) | J24: =IFERROR(VLOOKUP(I24,'Dummy Amount'!$A$2:$B$66,2,FALSE),0) -> 0 | L24: =IF($L$3="Y",IF($I24="",IF($K24<>"",$K24,""),$I24),"") | M24: =IF(L24="","",IF(I24<>"","Subject/Fixed","Inclusive")) | N24: =IFERROR(VLOOKUP(L24,'Dummy Amount'!A20:B84,2,FALSE),0) -> 0 | O24: =IF(L24="","",IF(I24="","No",IF(K24="","Yes","No"))) | P24: =IF($P$3="","",IF($P$3="LT_MRG",IF($H24="","",IF($G24="",$H24,"")),IF($H24="","",IF($F24="",$H24,"")))) | Q24: =IFERROR(VLOOKUP(P24,'Dummy Amount'!$A$2:$B$66,2,FALSE),0) -> 0 | R24: =IF(P24="","",IF(L24="","No","Yes")) | S24: =IF($S$3="","",IF($S$3="LT_MRG",IF($H24="","",IF($G24="",$H24,"")),IF($H24="","",IF($F24="",$H24,"")))) | T24: =IF($T$3="Y",IF($S24="",IF($L24<>"",$L24,""),$S24),"") | U24: =IF(T24="","",IF(S24<>"","Subject/Fixed","Inclusive")) | V24: =IFERROR(VLOOKUP(T24,'Dummy Amount'!$A$2:$B$66,2,FALSE),0) -> 0 | W24: =IF($W$3="","",IF($P$3="LT_MRG",IF($H24="","",IF($G24="",$H24,"")),IF($H24="","",IF($F24="",$H24,"")))) | X24: =IFERROR(VLOOKUP(W24,'Dummy Amount'!$A$2:$B$66,2,FALSE),0) -> 0 | Y24: =IF(W24="","",IF(T24="","No",IF(U24="Inclusive","No","Yes")))
B25: DOC | D25: DOC | H25: DOC | I25: =IF($I$3="","",IF($I$3="LT_MRG",IF($H25="","",IF($G25="",$H25,"")),IF($H25="","",IF($F25="",$H25,"")))) -> DOC | J25: =IFERROR(VLOOKUP(I25,'Dummy Amount'!$A$2:$B$66,2,FALSE),0) -> 50 | K25: DOC | L25: =IF($L$3="Y",IF($I25="",IF($K25<>"",$K25,""),$I25),"") -> DOC | M25: =IF(L25="","",IF(I25<>"","Subject/Fixed","Inclusive")) -> Subject/Fixed | N25: =IFERROR(VLOOKUP(L25,'Dummy Amount'!A21:B85,2,FALSE),0) -> 50 | O25: =IF(L25="","",IF(I25="","No",IF(K25="","Yes","No"))) -> No | P25: =IF($P$3="","",IF($P$3="LT_MRG",IF($H25="","",IF($G25="",$H25,"")),IF($H25="","",IF($F25="",$H25,"")))) -> DOC | Q25: =IFERROR(VLOOKUP(P25,'Dummy Amount'!$A$2:$B$66,2,FALSE),0) -> 50 | R25: =IF(P25="","",IF(L25="","No","Yes")) -> Yes | S25: =IF($S$3="","",IF($S$3="LT_MRG",IF($H25="","",IF($G25="",$H25,"")),IF($H25="","",IF($F25="",$H25,"")))) -> DOC | T25: =IF($T$3="Y",IF($S25="",IF($L25<>"",$L25,""),$S25),"") -> DOC | U25: =IF(T25="","",IF(S25<>"","Subject/Fixed","Inclusive")) -> Subject/Fixed | V25: =IFERROR(VLOOKUP(T25,'Dummy Amount'!$A$2:$B$66,2,FALSE),0) -> 50 | W25: =IF($W$3="","",IF($P$3="LT_MRG",IF($H25="","",IF($G25="",$H25,"")),IF($H25="","",IF($F25="",$H25,"")))) -> DOC | X25: =IFERROR(VLOOKUP(W25,'Dummy Amount'!$A$2:$B$66,2,FALSE),0) -> 50 | Y25: =IF(W25="","",IF(T25="","No",IF(U25="Inclusive","No","Yes"))) -> Yes
B26: DOF | D26: DOF | I26: =IF($I$3="","",IF($I$3="LT_MRG",IF($H26="","",IF($G26="",$H26,"")),IF($H26="","",IF($F26="",$H26,"")))) | J26: =IFERROR(VLOOKUP(I26,'Dummy Amount'!$A$2:$B$66,2,FALSE),0) -> 0 | K26: DOF | L26: =IF($L$3="Y",IF($I26="",IF($K26<>"",$K26,""),$I26),"") -> DOF | M26: =IF(L26="","",IF(I26<>"","Subject/Fixed","Inclusive")) -> Inclusive | N26: =IFERROR(VLOOKUP(L26,'Dummy Amount'!A22:B86,2,FALSE),0) -> 50 | O26: =IF(L26="","",IF(I26="","No",IF(K26="","Yes","No"))) -> No | P26: =IF($P$3="","",IF($P$3="LT_MRG",IF($H26="","",IF($G26="",$H26,"")),IF($H26="","",IF($F26="",$H26,"")))) | Q26: =IFERROR(VLOOKUP(P26,'Dummy Amount'!$A$2:$B$66,2,FALSE),0) -> 0 | R26: =IF(P26="","",IF(L26="","No","Yes")) | S26: =IF($S$3="","",IF($S$3="LT_MRG",IF($H26="","",IF($G26="",$H26,"")),IF($H26="","",IF($F26="",$H26,"")))) | T26: =IF($T$3="Y",IF($S26="",IF($L26<>"",$L26,""),$S26),"") -> DOF | U26: =IF(T26="","",IF(S26<>"","Subject/Fixed","Inclusive")) -> Inclusive | V26: =IFERROR(VLOOKUP(T26,'Dummy Amount'!$A$2:$B$66,2,FALSE),0) -> 50 | W26: =IF($W$3="","",IF($P$3="LT_MRG",IF($H26="","",IF($G26="",$H26,"")),IF($H26="","",IF($F26="",$H26,"")))) | X26: =IFERROR(VLOOKUP(W26,'Dummy Amount'!$A$2:$B$66,2,FALSE),0) -> 0 | Y26: =IF(W26="","",IF(T26="","No",IF(U26="Inclusive","No","Yes")))
I27: =IF($I$3="","",IF($I$3="LT_MRG",IF($H27="","",IF($G27="",$H27,"")),IF($H27="","",IF($F27="",$H27,"")))) | J27: =IFERROR(VLOOKUP(I27,'Dummy Amount'!$A$2:$B$66,2,FALSE),0) -> 0 | K27: DRP | L27: =IF($L$3="Y",IF($I27="",IF($K27<>"",$K27,""),$I27),"") -> DRP | M27: =IF(L27="","",IF(I27<>"","Subject/Fixed","Inclusive")) -> Inclusive | N27: =IFERROR(VLOOKUP(L27,'Dummy Amount'!A23:B87,2,FALSE),0) -> 50 | O27: =IF(L27="","",IF(I27="","No",IF(K27="","Yes","No"))) -> No | P27: =IF($P$3="","",IF($P$3="LT_MRG",IF($H27="","",IF($G27="",$H27,"")),IF($H27="","",IF($F27="",$H27,"")))) | Q27: =IFERROR(VLOOKUP(P27,'Dummy Amount'!$A$2:$B$66,2,FALSE),0) -> 0 | R27: =IF(P27="","",IF(L27="","No","Yes")) | S27: =IF($S$3="","",IF($S$3="LT_MRG",IF($H27="","",IF($G27="",$H27,"")),IF($H27="","",IF($F27="",$H27,"")))) | T27: =IF($T$3="Y",IF($S27="",IF($L27<>"",$L27,""),$S27),"") -> DRP | U27: =IF(T27="","",IF(S27<>"","Subject/Fixed","Inclusive")) -> Inclusive | V27: =IFERROR(VLOOKUP(T27,'Dummy Amount'!$A$2:$B$66,2,FALSE),0) -> 50 | W27: =IF($W$3="","",IF($P$3="LT_MRG",IF($H27="","",IF($G27="",$H27,"")),IF($H27="","",IF($F27="",$H27,"")))) | X27: =IFERROR(VLOOKUP(W27,'Dummy Amount'!$A$2:$B$66,2,FALSE),0) -> 0 | Y27: =IF(W27="","",IF(T27="","No",IF(U27="Inclusive","No","Yes")))
B28: ECA | F28: ECA | G28: ECA | H28: ECA | I28: =IF($I$3="","",IF($I$3="LT_MRG",IF($H28="","",IF($G28="",$H28,"")),IF($H28="","",IF($F28="",$H28,"")))) | J28: =IFERROR(VLOOKUP(I28,'Dummy Amount'!$A$2:$B$66,2,FALSE),0) -> 0 | K28: ECA | L28: =IF($L$3="Y",IF($I28="",IF($K28<>"",$K28,""),$I28),"") -> ECA | M28: =IF(L28="","",IF(I28<>"","Subject/Fixed","Inclusive")) -> Inclusive | N28: =IFERROR(VLOOKUP(L28,'Dummy Amount'!A24:B88,2,FALSE),0) -> 50 | O28: =IF(L28="","",IF(I28="","No",IF(K28="","Yes","No"))) -> No | P28: =IF($P$3="","",IF($P$3="LT_MRG",IF($H28="","",IF($G28="",$H28,"")),IF($H28="","",IF($F28="",$H28,"")))) | Q28: =IFERROR(VLOOKUP(P28,'Dummy Amount'!$A$2:$B$66,2,FALSE),0) -> 0 | R28: =IF(P28="","",IF(L28="","No","Yes")) | S28: =IF($S$3="","",IF($S$3="LT_MRG",IF($H28="","",IF($G28="",$H28,"")),IF($H28="","",IF($F28="",$H28,"")))) | T28: =IF($T$3="Y",IF($S28="",IF($L28<>"",$L28,""),$S28),"") -> ECA | U28: =IF(T28="","",IF(S28<>"","Subject/Fixed","Inclusive")) -> Inclusive | V28: =IFERROR(VLOOKUP(T28,'Dummy Amount'!$A$2:$B$66,2,FALSE),0) -> 50 | W28: =IF($W$3="","",IF($P$3="LT_MRG",IF($H28="","",IF($G28="",$H28,"")),IF($H28="","",IF($F28="",$H28,"")))) | X28: =IFERROR(VLOOKUP(W28,'Dummy Amount'!$A$2:$B$66,2,FALSE),0) -> 0 | Y28: =IF(W28="","",IF(T28="","No",IF(U28="Inclusive","No","Yes")))
B29: EEC | F29: EEC | I29: =IF($I$3="","",IF($I$3="LT_MRG",IF($H29="","",IF($G29="",$H29,"")),IF($H29="","",IF($F29="",$H29,"")))) | J29: =IFERROR(VLOOKUP(I29,'Dummy Amount'!$A$2:$B$66,2,FALSE),0) -> 0 | L29: =IF($L$3="Y",IF($I29="",IF($K29<>"",$K29,""),$I29),"") | M29: =IF(L29="","",IF(I29<>"","Subject/Fixed","Inclusive")) | N29: =IFERROR(VLOOKUP(L29,'Dummy Amount'!A25:B89,2,FALSE),0) -> 0 | O29: =IF(L29="","",IF(I29="","No",IF(K29="","Yes","No"))) | P29: =IF($P$3="","",IF($P$3="LT_MRG",IF($H29="","",IF($G29="",$H29,"")),IF($H29="","",IF($F29="",$H29,"")))) | Q29: =IFERROR(VLOOKUP(P29,'Dummy Amount'!$A$2:$B$66,2,FALSE),0) -> 0 | R29: =IF(P29="","",IF(L29="","No","Yes")) | S29: =IF($S$3="","",IF($S$3="LT_MRG",IF($H29="","",IF($G29="",$H29,"")),IF($H29="","",IF($F29="",$H29,"")))) | T29: =IF($T$3="Y",IF($S29="",IF($L29<>"",$L29,""),$S29),"") | U29: =IF(T29="","",IF(S29<>"","Subject/Fixed","Inclusive")) | V29: =IFERROR(VLOOKUP(T29,'Dummy Amount'!$A$2:$B$66,2,FALSE),0) -> 0 | W29: =IF($W$3="","",IF($P$3="LT_MRG",IF($H29="","",IF($G29="",$H29,"")),IF($H29="","",IF($F29="",$H29,"")))) | X29: =IFERROR(VLOOKUP(W29,'Dummy Amount'!$A$2:$B$66,2,FALSE),0) -> 0 | Y29: =IF(W29="","",IF(T29="","No",IF(U29="Inclusive","No","Yes")))
B30: EHL | F30: EHL | I30: =IF($I$3="","",IF($I$3="LT_MRG",IF($H30="","",IF($G30="",$H30,"")),IF($H30="","",IF($F30="",$H30,"")))) | J30: =IFERROR(VLOOKUP(I30,'Dummy Amount'!$A$2:$B$66,2,FALSE),0) -> 0 | L30: =IF($L$3="Y",IF($I30="",IF($K30<>"",$K30,""),$I30),"") | M30: =IF(L30="","",IF(I30<>"","Subject/Fixed","Inclusive")) | N30: =IFERROR(VLOOKUP(L30,'Dummy Amount'!A26:B90,2,FALSE),0) -> 0 | O30: =IF(L30="","",IF(I30="","No",IF(K30="","Yes","No"))) | P30: =IF($P$3="","",IF($P$3="LT_MRG",IF($H30="","",IF($G30="",$H30,"")),IF($H30="","",IF($F30="",$H30,"")))) | Q30: =IFERROR(VLOOKUP(P30,'Dummy Amount'!$A$2:$B$66,2,FALSE),0) -> 0 | R30: =IF(P30="","",IF(L30="","No","Yes")) | S30: =IF($S$3="","",IF($S$3="LT_MRG",IF($H30="","",IF($G30="",$H30,"")),IF($H30="","",IF($F30="",$H30,"")))) | T30: =IF($T$3="Y",IF($S30="",IF($L30<>"",$L30,""),$S30),"") | U30: =IF(T30="","",IF(S30<>"","Subject/Fixed","Inclusive")) | V30: =IFERROR(VLOOKUP(T30,'Dummy Amount'!$A$2:$B$66,2,FALSE),0) -> 0 | W30: =IF($W$3="","",IF($P$3="LT_MRG",IF($H30="","",IF($G30="",$H30,"")),IF($H30="","",IF($F30="",$H30,"")))) | X30: =IFERROR(VLOOKUP(W30,'Dummy Amount'!$A$2:$B$66,2,FALSE),0) -> 0 | Y30: =IF(W30="","",IF(T30="","No",IF(U30="Inclusive","No","Yes")))
B31: EIS | F31: EIS | I31: =IF($I$3="","",IF($I$3="LT_MRG",IF($H31="","",IF($G31="",$H31,"")),IF($H31="","",IF($F31="",$H31,"")))) | J31: =IFERROR(VLOOKUP(I31,'Dummy Amount'!$A$2:$B$66,2,FALSE),0) -> 0 | L31: =IF($L$3="Y",IF($I31="",IF($K31<>"",$K31,""),$I31),"") | M31: =IF(L31="","",IF(I31<>"","Subject/Fixed","Inclusive")) | N31: =IFERROR(VLOOKUP(L31,'Dummy Amount'!A27:B91,2,FALSE),0) -> 0 | O31: =IF(L31="","",IF(I31="","No",IF(K31="","Yes","No"))) | P31: =IF($P$3="","",IF($P$3="LT_MRG",IF($H31="","",IF($G31="",$H31,"")),IF($H31="","",IF($F31="",$H31,"")))) | Q31: =IFERROR(VLOOKUP(P31,'Dummy Amount'!$A$2:$B$66,2,FALSE),0) -> 0 | R31: =IF(P31="","",IF(L31="","No","Yes")) | S31: =IF($S$3="","",IF($S$3="LT_MRG",IF($H31="","",IF($G31="",$H31,"")),IF($H31="","",IF($F31="",$H31,"")))) | T31: =IF($T$3="Y",IF($S31="",IF($L31<>"",$L31,""),$S31),"") | U31: =IF(T31="","",IF(S31<>"","Subject/Fixed","Inclusive")) | V31: =IFERROR(VLOOKUP(T31,'Dummy Amount'!$A$2:$B$66,2,FALSE),0) -> 0 | W31: =IF($W$3="","",IF($P$3="LT_MRG",IF($H31="","",IF($G31="",$H31,"")),IF($H31="","",IF($F31="",$H31,"")))) | X31: =IFERROR(VLOOKUP(W31,'Dummy Amount'!$A$2:$B$66,2,FALSE),0) -> 0 | Y31: =IF(W31="","",IF(T31="","No",IF(U31="Inclusive","No","Yes")))
B32: ESD | F32: ESD | I32: =IF($I$3="","",IF($I$3="LT_MRG",IF($H32="","",IF($G32="",$H32,"")),IF($H32="","",IF($F32="",$H32,"")))) | J32: =IFERROR(VLOOKUP(I32,'Dummy Amount'!$A$2:$B$66,2,FALSE),0) -> 0 | L32: =IF($L$3="Y",IF($I32="",IF($K32<>"",$K32,""),$I32),"") | M32: =IF(L32="","",IF(I32<>"","Subject/Fixed","Inclusive")) | N32: =IFERROR(VLOOKUP(L32,'Dummy Amount'!A28:B92,2,FALSE),0) -> 0 | O32: =IF(L32="","",IF(I32="","No",IF(K32="","Yes","No"))) | P32: =IF($P$3="","",IF($P$3="LT_MRG",IF($H32="","",IF($G32="",$H32,"")),IF($H32="","",IF($F32="",$H32,"")))) | Q32: =IFERROR(VLOOKUP(P32,'Dummy Amount'!$A$2:$B$66,2,FALSE),0) -> 0 | R32: =IF(P32="","",IF(L32="","No","Yes")) | S32: =IF($S$3="","",IF($S$3="LT_MRG",IF($H32="","",IF($G32="",$H32,"")),IF($H32="","",IF($F32="",$H32,"")))) | T32: =IF($T$3="Y",IF($S32="",IF($L32<>"",$L32,""),$S32),"") | U32: =IF(T32="","",IF(S32<>"","Subject/Fixed","Inclusive")) | V32: =IFERROR(VLOOKUP(T32,'Dummy Amount'!$A$2:$B$66,2,FALSE),0) -> 0 | W32: =IF($W$3="","",IF($P$3="LT_MRG",IF($H32="","",IF($G32="",$H32,"")),IF($H32="","",IF($F32="",$H32,"")))) | X32: =IFERROR(VLOOKUP(W32,'Dummy Amount'!$A$2:$B$66,2,FALSE),0) -> 0 | Y32: =IF(W32="","",IF(T32="","No",IF(U32="Inclusive","No","Yes")))
B33: FED | F33: FED | I33: =IF($I$3="","",IF($I$3="LT_MRG",IF($H33="","",IF($G33="",$H33,"")),IF($H33="","",IF($F33="",$H33,"")))) | J33: =IFERROR(VLOOKUP(I33,'Dummy Amount'!$A$2:$B$66,2,FALSE),0) -> 0 | L33: =IF($L$3="Y",IF($I33="",IF($K33<>"",$K33,""),$I33),"") | M33: =IF(L33="","",IF(I33<>"","Subject/Fixed","Inclusive")) | N33: =IFERROR(VLOOKUP(L33,'Dummy Amount'!A29:B93,2,FALSE),0) -> 0 | O33: =IF(L33="","",IF(I33="","No",IF(K33="","Yes","No"))) | P33: =IF($P$3="","",IF($P$3="LT_MRG",IF($H33="","",IF($G33="",$H33,"")),IF($H33="","",IF($F33="",$H33,"")))) | Q33: =IFERROR(VLOOKUP(P33,'Dummy Amount'!$A$2:$B$66,2,FALSE),0) -> 0 | R33: =IF(P33="","",IF(L33="","No","Yes")) | S33: =IF($S$3="","",IF($S$3="LT_MRG",IF($H33="","",IF($G33="",$H33,"")),IF($H33="","",IF($F33="",$H33,"")))) | T33: =IF($T$3="Y",IF($S33="",IF($L33<>"",$L33,""),$S33),"") | U33: =IF(T33="","",IF(S33<>"","Subject/Fixed","Inclusive")) | V33: =IFERROR(VLOOKUP(T33,'Dummy Amount'!$A$2:$B$66,2,FALSE),0) -> 0 | W33: =IF($W$3="","",IF($P$3="LT_MRG",IF($H33="","",IF($G33="",$H33,"")),IF($H33="","",IF($F33="",$H33,"")))) | X33: =IFERROR(VLOOKUP(W33,'Dummy Amount'!$A$2:$B$66,2,FALSE),0) -> 0 | Y33: =IF(W33="","",IF(T33="","No",IF(U33="Inclusive","No","Yes")))
B34: FGP | D34: FGP | I34: =IF($I$3="","",IF($I$3="LT_MRG",IF($H34="","",IF($G34="",$H34,"")),IF($H34="","",IF($F34="",$H34,"")))) | J34: =IFERROR(VLOOKUP(I34,'Dummy Amount'!$A$2:$B$66,2,FALSE),0) -> 0 | L34: =IF($L$3="Y",IF($I34="",IF($K34<>"",$K34,""),$I34),"") | M34: =IF(L34="","",IF(I34<>"","Subject/Fixed","Inclusive")) | N34: =IFERROR(VLOOKUP(L34,'Dummy Amount'!A30:B94,2,FALSE),0) -> 0 | O34: =IF(L34="","",IF(I34="","No",IF(K34="","Yes","No"))) | P34: =IF($P$3="","",IF($P$3="LT_MRG",IF($H34="","",IF($G34="",$H34,"")),IF($H34="","",IF($F34="",$H34,"")))) | Q34: =IFERROR(VLOOKUP(P34,'Dummy Amount'!$A$2:$B$66,2,FALSE),0) -> 0 | R34: =IF(P34="","",IF(L34="","No","Yes")) | S34: =IF($S$3="","",IF($S$3="LT_MRG",IF($H34="","",IF($G34="",$H34,"")),IF($H34="","",IF($F34="",$H34,"")))) | T34: =IF($T$3="Y",IF($S34="",IF($L34<>"",$L34,""),$S34),"") | U34: =IF(T34="","",IF(S34<>"","Subject/Fixed","Inclusive")) | V34: =IFERROR(VLOOKUP(T34,'Dummy Amount'!$A$2:$B$66,2,FALSE),0) -> 0 | W34: =IF($W$3="","",IF($P$3="LT_MRG",IF($H34="","",IF($G34="",$H34,"")),IF($H34="","",IF($F34="",$H34,"")))) | X34: =IFERROR(VLOOKUP(W34,'Dummy Amount'!$A$2:$B$66,2,FALSE),0) -> 0 | Y34: =IF(W34="","",IF(T34="","No",IF(U34="Inclusive","No","Yes")))
I35: =IF($I$3="","",IF($I$3="LT_MRG",IF($H35="","",IF($G35="",$H35,"")),IF($H35="","",IF($F35="",$H35,"")))) | J35: =IFERROR(VLOOKUP(I35,'Dummy Amount'!$A$2:$B$66,2,FALSE),0) -> 0 | K35: FI | L35: =IF($L$3="Y",IF($I35="",IF($K35<>"",$K35,""),$I35),"") -> FI | M35: =IF(L35="","",IF(I35<>"","Subject/Fixed","Inclusive")) -> Inclusive | N35: =IFERROR(VLOOKUP(L35,'Dummy Amount'!A31:B95,2,FALSE),0) -> 50 | O35: =IF(L35="","",IF(I35="","No",IF(K35="","Yes","No"))) -> No | P35: =IF($P$3="","",IF($P$3="LT_MRG",IF($H35="","",IF($G35="",$H35,"")),IF($H35="","",IF($F35="",$H35,"")))) | Q35: =IFERROR(VLOOKUP(P35,'Dummy Amount'!$A$2:$B$66,2,FALSE),0) -> 0 | R35: =IF(P35="","",IF(L35="","No","Yes")) | S35: =IF($S$3="","",IF($S$3="LT_MRG",IF($H35="","",IF($G35="",$H35,"")),IF($H35="","",IF($F35="",$H35,"")))) | T35: =IF($T$3="Y",IF($S35="",IF($L35<>"",$L35,""),$S35),"") -> FI | U35: =IF(T35="","",IF(S35<>"","Subject/Fixed","Inclusive")) -> Inclusive | V35: =IFERROR(VLOOKUP(T35,'Dummy Amount'!$A$2:$B$66,2,FALSE),0) -> 50 | W35: =IF($W$3="","",IF($P$3="LT_MRG",IF($H35="","",IF($G35="",$H35,"")),IF($H35="","",IF($F35="",$H35,"")))) | X35: =IFERROR(VLOOKUP(W35,'Dummy Amount'!$A$2:$B$66,2,FALSE),0) -> 0 | Y35: =IF(W35="","",IF(T35="","No",IF(U35="Inclusive","No","Yes")))
I36: =IF($I$3="","",IF($I$3="LT_MRG",IF($H36="","",IF($G36="",$H36,"")),IF($H36="","",IF($F36="",$H36,"")))) | J36: =IFERROR(VLOOKUP(I36,'Dummy Amount'!$A$2:$B$66,2,FALSE),0) -> 0 | K36: FO | L36: =IF($L$3="Y",IF($I36="",IF($K36<>"",$K36,""),$I36),"") -> FO | M36: =IF(L36="","",IF(I36<>"","Subject/Fixed","Inclusive")) -> Inclusive | N36: =IFERROR(VLOOKUP(L36,'Dummy Amount'!A32:B96,2,FALSE),0) -> 50 | O36: =IF(L36="","",IF(I36="","No",IF(K36="","Yes","No"))) -> No | P36: =IF($P$3="","",IF($P$3="LT_MRG",IF($H36="","",IF($G36="",$H36,"")),IF($H36="","",IF($F36="",$H36,"")))) | Q36: =IFERROR(VLOOKUP(P36,'Dummy Amount'!$A$2:$B$66,2,FALSE),0) -> 0 | R36: =IF(P36="","",IF(L36="","No","Yes")) | S36: =IF($S$3="","",IF($S$3="LT_MRG",IF($H36="","",IF($G36="",$H36,"")),IF($H36="","",IF($F36="",$H36,"")))) | T36: =IF($T$3="Y",IF($S36="",IF($L36<>"",$L36,""),$S36),"") -> FO | U36: =IF(T36="","",IF(S36<>"","Subject/Fixed","Inclusive")) -> Inclusive | V36: =IFERROR(VLOOKUP(T36,'Dummy Amount'!$A$2:$B$66,2,FALSE),0) -> 50 | W36: =IF($W$3="","",IF($P$3="LT_MRG",IF($H36="","",IF($G36="",$H36,"")),IF($H36="","",IF($F36="",$H36,"")))) | X36: =IFERROR(VLOOKUP(W36,'Dummy Amount'!$A$2:$B$66,2,FALSE),0) -> 0 | Y36: =IF(W36="","",IF(T36="","No",IF(U36="Inclusive","No","Yes")))
B37: GAT | F37: GAT | H37: GAT | I37: =IF($I$3="","",IF($I$3="LT_MRG",IF($H37="","",IF($G37="",$H37,"")),IF($H37="","",IF($F37="",$H37,"")))) | J37: =IFERROR(VLOOKUP(I37,'Dummy Amount'!$A$2:$B$66,2,FALSE),0) -> 0 | L37: =IF($L$3="Y",IF($I37="",IF($K37<>"",$K37,""),$I37),"") | M37: =IF(L37="","",IF(I37<>"","Subject/Fixed","Inclusive")) | N37: =IFERROR(VLOOKUP(L37,'Dummy Amount'!A33:B97,2,FALSE),0) -> 0 | O37: =IF(L37="","",IF(I37="","No",IF(K37="","Yes","No"))) | P37: =IF($P$3="","",IF($P$3="LT_MRG",IF($H37="","",IF($G37="",$H37,"")),IF($H37="","",IF($F37="",$H37,"")))) -> GAT | Q37: =IFERROR(VLOOKUP(P37,'Dummy Amount'!$A$2:$B$66,2,FALSE),0) -> 33 | R37: =IF(P37="","",IF(L37="","No","Yes")) -> No | S37: =IF($S$3="","",IF($S$3="LT_MRG",IF($H37="","",IF($G37="",$H37,"")),IF($H37="","",IF($F37="",$H37,"")))) | T37: =IF($T$3="Y",IF($S37="",IF($L37<>"",$L37,""),$S37),"") | U37: =IF(T37="","",IF(S37<>"","Subject/Fixed","Inclusive")) | V37: =IFERROR(VLOOKUP(T37,'Dummy Amount'!$A$2:$B$66,2,FALSE),0) -> 0 | W37: =IF($W$3="","",IF($P$3="LT_MRG",IF($H37="","",IF($G37="",$H37,"")),IF($H37="","",IF($F37="",$H37,"")))) -> GAT | X37: =IFERROR(VLOOKUP(W37,'Dummy Amount'!$A$2:$B$66,2,FALSE),0) -> 33 | Y37: =IF(W37="","",IF(T37="","No",IF(U37="Inclusive","No","Yes"))) -> No
B38: GOH | F38: GOH | I38: =IF($I$3="","",IF($I$3="LT_MRG",IF($H38="","",IF($G38="",$H38,"")),IF($H38="","",IF($F38="",$H38,"")))) | J38: =IFERROR(VLOOKUP(I38,'Dummy Amount'!$A$2:$B$66,2,FALSE),0) -> 0 | L38: =IF($L$3="Y",IF($I38="",IF($K38<>"",$K38,""),$I38),"") | M38: =IF(L38="","",IF(I38<>"","Subject/Fixed","Inclusive")) | N38: =IFERROR(VLOOKUP(L38,'Dummy Amount'!A34:B98,2,FALSE),0) -> 0 | O38: =IF(L38="","",IF(I38="","No",IF(K38="","Yes","No"))) | P38: =IF($P$3="","",IF($P$3="LT_MRG",IF($H38="","",IF($G38="",$H38,"")),IF($H38="","",IF($F38="",$H38,"")))) | Q38: =IFERROR(VLOOKUP(P38,'Dummy Amount'!$A$2:$B$66,2,FALSE),0) -> 0 | R38: =IF(P38="","",IF(L38="","No","Yes")) | S38: =IF($S$3="","",IF($S$3="LT_MRG",IF($H38="","",IF($G38="",$H38,"")),IF($H38="","",IF($F38="",$H38,"")))) | T38: =IF($T$3="Y",IF($S38="",IF($L38<>"",$L38,""),$S38),"") | U38: =IF(T38="","",IF(S38<>"","Subject/Fixed","Inclusive")) | V38: =IFERROR(VLOOKUP(T38,'Dummy Amount'!$A$2:$B$66,2,FALSE),0) -> 0 | W38: =IF($W$3="","",IF($P$3="LT_MRG",IF($H38="","",IF($G38="",$H38,"")),IF($H38="","",IF($F38="",$H38,"")))) | X38: =IFERROR(VLOOKUP(W38,'Dummy Amount'!$A$2:$B$66,2,FALSE),0) -> 0 | Y38: =IF(W38="","",IF(T38="","No",IF(U38="Inclusive","No","Yes")))
B39: HAU | F39: HAU | I39: =IF($I$3="","",IF($I$3="LT_MRG",IF($H39="","",IF($G39="",$H39,"")),IF($H39="","",IF($F39="",$H39,"")))) | J39: =IFERROR(VLOOKUP(I39,'Dummy Amount'!$A$2:$B$66,2,FALSE),0) -> 0 | L39: =IF($L$3="Y",IF($I39="",IF($K39<>"",$K39,""),$I39),"") | M39: =IF(L39="","",IF(I39<>"","Subject/Fixed","Inclusive")) | N39: =IFERROR(VLOOKUP(L39,'Dummy Amount'!A35:B99,2,FALSE),0) -> 0 | O39: =IF(L39="","",IF(I39="","No",IF(K39="","Yes","No"))) | P39: =IF($P$3="","",IF($P$3="LT_MRG",IF($H39="","",IF($G39="",$H39,"")),IF($H39="","",IF($F39="",$H39,"")))) | Q39: =IFERROR(VLOOKUP(P39,'Dummy Amount'!$A$2:$B$66,2,FALSE),0) -> 0 | R39: =IF(P39="","",IF(L39="","No","Yes")) | S39: =IF($S$3="","",IF($S$3="LT_MRG",IF($H39="","",IF($G39="",$H39,"")),IF($H39="","",IF($F39="",$H39,"")))) | T39: =IF($T$3="Y",IF($S39="",IF($L39<>"",$L39,""),$S39),"") | U39: =IF(T39="","",IF(S39<>"","Subject/Fixed","Inclusive")) | V39: =IFERROR(VLOOKUP(T39,'Dummy Amount'!$A$2:$B$66,2,FALSE),0) -> 0 | W39: =IF($W$3="","",IF($P$3="LT_MRG",IF($H39="","",IF($G39="",$H39,"")),IF($H39="","",IF($F39="",$H39,"")))) | X39: =IFERROR(VLOOKUP(W39,'Dummy Amount'!$A$2:$B$66,2,FALSE),0) -> 0 | Y39: =IF(W39="","",IF(T39="","No",IF(U39="Inclusive","No","Yes")))
B40: HAZ | F40: HAZ | I40: =IF($I$3="","",IF($I$3="LT_MRG",IF($H40="","",IF($G40="",$H40,"")),IF($H40="","",IF($F40="",$H40,"")))) | J40: =IFERROR(VLOOKUP(I40,'Dummy Amount'!$A$2:$B$66,2,FALSE),0) -> 0 | K40: HAZ | L40: =IF($L$3="Y",IF($I40="",IF($K40<>"",$K40,""),$I40),"") -> HAZ | M40: =IF(L40="","",IF(I40<>"","Subject/Fixed","Inclusive")) -> Inclusive | N40: =IFERROR(VLOOKUP(L40,'Dummy Amount'!A36:B100,2,FALSE),0) -> 50 | O40: =IF(L40="","",IF(I40="","No",IF(K40="","Yes","No"))) -> No | P40: =IF($P$3="","",IF($P$3="LT_MRG",IF($H40="","",IF($G40="",$H40,"")),IF($H40="","",IF($F40="",$H40,"")))) | Q40: =IFERROR(VLOOKUP(P40,'Dummy Amount'!$A$2:$B$66,2,FALSE),0) -> 0 | R40: =IF(P40="","",IF(L40="","No","Yes")) | S40: =IF($S$3="","",IF($S$3="LT_MRG",IF($H40="","",IF($G40="",$H40,"")),IF($H40="","",IF($F40="",$H40,"")))) | T40: =IF($T$3="Y",IF($S40="",IF($L40<>"",$L40,""),$S40),"") -> HAZ | U40: =IF(T40="","",IF(S40<>"","Subject/Fixed","Inclusive")) -> Inclusive | V40: =IFERROR(VLOOKUP(T40,'Dummy Amount'!$A$2:$B$66,2,FALSE),0) -> 50 | W40: =IF($W$3="","",IF($P$3="LT_MRG",IF($H40="","",IF($G40="",$H40,"")),IF($H40="","",IF($F40="",$H40,"")))) | X40: =IFERROR(VLOOKUP(W40,'Dummy Amount'!$A$2:$B$66,2,FALSE),0) -> 0 | Y40: =IF(W40="","",IF(T40="","No",IF(U40="Inclusive","No","Yes")))
...

Sheet Dummy Amount
A1: Surcharge | B1: Dummy Amount USD
A2: ADC | B2: 50
A3: ADD | B3: 50
A4: AHA | B4: 50
A5: AMS | B5: 50
A6: BSC | B6: 50
A7: CAF | B7: 50
A8: CCC | B8: 50
A9: CCU | B9: 50
A10: CFD | B10: 50
A11: CFD | B11: 50
A12: CGD | B12: 50
A13: CMC | B13: 50
... A66: XDL | B66: 50

Sheet Sheet2
A1: ADC | B1: ADD | C1: AHA | D1: BSC | E1: CAF | F1: CCC | G1: CCU | H1: CFD | I1: CFD | J1: CGD | K1: CMC | L1: CSS | M1: CVC | N1: DGS | O1: ECA | P1: EEC | Q1: EHL | R1: EIS | S1: ESD | T1: FED | U1: GAT | V1: GOH | W1: HAU | X1: HAZ | Y1: HEA | Z1: HHA | AA1: IFL | AB1: INP | AC1: INS | AD1: LID | AE1: LLO | AF1: LOG | AG1: LOT | AH1: MBF | AI1: NEO | AJ1: OCR | AK1: PSA | AL1: PSS | AM1: PUC | AN1: RMF | AO1: SCT | AP1: THL | AQ1: TSL | AR1: WHF | AS1: WHO | AT1: WRC | AU1: XCA | AV1: XDD | AW1: XDD | AX1: XDL
A2: CAF | B2: THL | C2: TSL | D2: SCT | E2: OBS | F2: ECA | G2: NEO
A3: CSS | B3: DOC | C3: ECA | D3: GAT | E3: LLO | F3: MBF | G3: OBS | H3: OCR | I3: SCT | J3: THL | K3: TSL | L3: XAF | M3: XDD
A5: OBS | B5: AMS | C5: DOF | D5: THD
A6: FGP | B6: DOC
A14: ADC,ADD,AHA,BSC,CAF,CCC,CCU,CFD,CFD,CGD,CMC,CSS,CVC,DGS,ECA,EEC,EHL,EIS,ESD,FED,GAT,GOH,HAU,HAZ,HEA,HHA,IFL,INP,INS,LID,LLO,LOG,LOT,MBF,NEO,OCR,PSA,PSS,PUC,RMF,SCT,THL,TSL,WHF,WHO,WRC,XCA,XDD,XDD,XDL
A17: CSS,DOC,ECA,GAT,LLO,MBF,OBS,OCR,SCT,THL,TSL,XAF,XDD
